Workbook

Sheet Sheet1
A1: 이름 | B1: 사번(온나라ID) | C1: 기관명_LDAP | D1: 조직부서 | E1: 기관명_LDAP | F1: 부서명 | G1: 직급 | H1: 휴대전화번호 | I1: 입사일
A2: 김영훈 | B2: 050025169 | C2: 1492001 | D2: 고용노동부.장관실 | E2: =VLOOKUP(D2,Sheet2!$A$1:$B$733,2,0) -> 1492001 | F2: 장관실 | G2: 장관 | J2: 공무원
A3: 윤권상 | B3: 000007497 | C3: 1492001 | D3: 고용노동부.장관실.비서실 | E3: =VLOOKUP(D3,Sheet2!$A$1:$B$733,2,0) -> 1492001 | F3: 비서실 | G3: 서기관 | H3: 010-2840-7235 | I3: 2003.04.07
A4: 명성호 | B4: 050018699 | C4: 1492001 | D4: 고용노동부.장관실.비서실 | E4: =VLOOKUP(D4,Sheet2!$A$1:$B$733,2,0) -> 1492001 | F4: 비서실 | G4: 행정사무관 | H4: 010-9021-7013 / 010-2054-7427 | I4: 2021.09.04
A5: 임용태 | B5: 050007746 | C5: 1492001 | D5: 고용노동부.장관실.비서실 | E5: =VLOOKUP(D5,Sheet2!$A$1:$B$733,2,0) -> 1492001 | F5: 비서실 | G5: 별정직6급상당 | H5: 010-8580-7848 | I5: 2018.08.20
A6: 이정원 | B6: 050009002 | C6: 1492001 | D6: 고용노동부.장관실.비서실 | E6: =VLOOKUP(D6,Sheet2!$A$1:$B$733,2,0) -> 1492001 | F6: 비서실 | G6: 행정주사보 | H6: 010-2126-2621 | I6: 2019.11.20
A7: 강정애 | B7: 000000469 | C7: 1492001 | D7: 고용노동부.장관실.비서실 | E7: =VLOOKUP(D7,Sheet2!$A$1:$B$733,2,0) -> 1492001 | F7: 비서실 | G7: 사무운영주사보 | H7: 010-8947-7883 | I7: 1996.08.13
A8: 박재철 | B8: 050025309 | C8: 1493690 | D8: 고용노동부.장관실.장관정책보좌관실 | E8: =VLOOKUP(D8,Sheet2!$A$1:$B$733,2,0) -> 1493690 | F8: 장관정책보좌관실 | G8: 별정직고위공무원(장관정책보좌관) | H8: 010-5299-0615 | I8: 2025.09.01
A9: 권택흥 | B9: 050025305 | C9: 1493690 | D9: 고용노동부.장관실.장관정책보좌관실 | E9: =VLOOKUP(D9,Sheet2!$A$1:$B$733,2,0) -> 1493690 | F9: 장관정책보좌관실 | G9: 별정직3급상당(장관정책보좌관) | H9: 010-3513-2785 | I9: 2025.08.27
A10: 임소형 | B10: 050021379 | C10: 1493690 | D10: 고용노동부.장관실.장관정책보좌관실 | E10: =VLOOKUP(D10,Sheet2!$A$1:$B$733,2,0) -> 1493690 | F10: 장관정책보좌관실 | G10: 전문임기제다급 | H10: 010-8802-2073 | I10: #N/A | J10: 공무원
A11: 공은진 | B11: 050009310 | C11: 1493690 | D11: 고용노동부.장관실.장관정책보좌관실 | E11: =VLOOKUP(D11,Sheet2!$A$1:$B$733,2,0) -> 1493690 | F11: 장관정책보좌관실 | G11: 행정주사보 | H11: 010-7225-7475 | I11: 2019.08.12
A12: 권창준 | B12: 000004595 | C12: 1492002 | D12: 고용노동부.차관실 | E12: =VLOOKUP(D12,Sheet2!$A$1:$B$733,2,0) -> 1492002 | F12: 차관실 | G12: 차관 | H12: - | I12: 1997.04.14
A13: 박지영 | B13: 020043770 | C13: 1492002 | D13: 고용노동부.차관실.비서실 | E13: =VLOOKUP(D13,Sheet2!$A$1:$B$733,2,0) -> 1492002 | F13: 비서실 | G13: 행정사무관 | H13: 010-4582-7014 | I13: 2007.02.07
A14: 이정구 | B14: 050004301 | C14: 1492002 | D14: 고용노동부.차관실.비서실 | E14: =VLOOKUP(D14,Sheet2!$A$1:$B$733,2,0) -> 1492002 | F14: 비서실 | G14: 별정직6급상당 | H14: 010-9699-8379 | I14: 2018.03.05
A15: 이정주 | B15: 050014748 | C15: 1492002 | D15: 고용노동부.차관실.비서실 | E15: =VLOOKUP(D15,Sheet2!$A$1:$B$733,2,0) -> 1492002 | F15: 비서실 | G15: 행정주사보 | H15: 010-7192-3724 | I15: 2020.12.28
A16: 홍경의 | B16: 000006379 | C16: 1493687 | D16: 고용노동부.대변인 | E16: =VLOOKUP(D16,Sheet2!$A$1:$B$733,2,0) -> 1493687 | F16: 대변인 | G16: 일반직고위공무원 | H16: 010-6265-2817 | I16: 2001.04.09
A17: 노경민 | B17: 010128162 | C17: 1492992 | D17: 고용노동부.대변인.홍보담당관 | E17: =VLOOKUP(D17,Sheet2!$A$1:$B$733,2,0) -> 1492992 | F17: 홍보담당관 | G17: 서기관 | H17: 010-9063-1632 | I17: 2010.04.26
A18: 최재훈 | B18: 050007337 | C18: 1492992 | D18: 고용노동부.대변인.홍보담당관 | E18: =VLOOKUP(D18,Sheet2!$A$1:$B$733,2,0) -> 1492992 | F18: 홍보담당관 | G18: 시설사무관 | H18: 010-9441-6370 | I18: 2017.09.09
A19: 김영훈 | B19: 010032190 | C19: 1492992 | D19: 고용노동부.대변인.홍보담당관 | E19: =VLOOKUP(D19,Sheet2!$A$1:$B$733,2,0) -> 1492992 | F19: 홍보담당관 | G19: 행정사무관 | H19: 010-4912-5319 | I19: 2006.03.13
A20: 박수용 | B20: 020121557 | C20: 1492992 | D20: 고용노동부.대변인.홍보담당관 | E20: =VLOOKUP(D20,Sheet2!$A$1:$B$733,2,0) -> 1492992 | F20: 홍보담당관 | G20: 행정사무관 | H20: 010-3558-7190 | I20: 2010.01.22
A21: 권도연 | B21: 050021709 | C21: 1492992 | D21: 고용노동부.대변인.홍보담당관 | E21: =VLOOKUP(D21,Sheet2!$A$1:$B$733,2,0) -> 1492992 | F21: 홍보담당관 | G21: 전문임기제 나급 | H21: 010-6511-3171 | I21: 2023.03.27
A22: 박인환 | B22: 000000127 | C22: 1492992 | D22: 고용노동부.대변인.홍보담당관 | E22: =VLOOKUP(D22,Sheet2!$A$1:$B$733,2,0) -> 1492992 | F22: 홍보담당관 | G22: 전문경력관 나군 | H22: 010-6251-6458 | I22: 1995.05.26
... A34: 구경훈 | B34: 030142355 | C34: 1494930 | D34: 고용노동부.대변인.디지털소통팀 | E34: =VLOOKUP(D34,Sheet2!$A$1:$B$733,2,0) -> 1494930 | F34: 디지털소통팀 | G34: 행정주사 | H34: 010-2707-4452 | I34: 2011.07.04
A35: 김신동 | B35: 050008007 | C35: 1494930 | D35: 고용노동부.대변인.디지털소통팀 | E35: =VLOOKUP(D35,Sheet2!$A$1:$B$733,2,0) -> 1494930 | F35: 디지털소통팀 | G35: 전문임기제다급 | H35: 01086438259 | I35: #N/A | J35: 공무원
A36: 안현주 | B36: 050008008 | C36: 1494930 | D36: 고용노동부.대변인.디지털소통팀 | E36: =VLOOKUP(D36,Sheet2!$A$1:$B$733,2,0) -> 1494930 | F36: 디지털소통팀 | G36: 전문임기제다급 | H36: 01046883014 | I36: #N/A | J36: 공무원
A37: 양정원 | B37: 010172675 | C37: 1494930 | D37: 고용노동부.대변인.디지털소통팀 | E37: =VLOOKUP(D37,Sheet2!$A$1:$B$733,2,0) -> 1494930 | F37: 디지털소통팀 | G37: 행정주사보 | H37: 010-9437-3597 | I37: 2013.01.01
A38: 김달님 | B38: 050008087 | C38: 1494930 | D38: 고용노동부.대변인.디지털소통팀 | E38: =VLOOKUP(D38,Sheet2!$A$1:$B$733,2,0) -> 1494930 | F38: 디지털소통팀 | G38: 행정서기 | H38: 010-2893-3974 | I38: 2018.12.11
A39: 오태웅 | B39: 000000261 | C39: 1493631 | D39: 고용노동부.감사관.감사담당관 | E39: =VLOOKUP(D39,Sheet2!$A$1:$B$733,2,0) -> 1493631 | F39: 감사담당관 | G39: 부이사관 | H39: 010-7252-2967 | I39: 1989.10.05
A40: 박수호 | B40: 000001570 | C40: 1493631 | D40: 고용노동부.감사관.감사담당관 | E40: =VLOOKUP(D40,Sheet2!$A$1:$B$733,2,0) -> 1493631 | F40: 감사담당관 | G40: 서기관 | H40: 010-8572-3874 | I40: 1997.09.22
A41: 전종포 | B41: 030011057 | C41: 1493631 | D41: 고용노동부.감사관.감사담당관 | E41: =VLOOKUP(D41,Sheet2!$A$1:$B$733,2,0) -> 1493631 | F41: 감사담당관 | G41: 행정사무관 | H41: 010-8863-9674 | I41: 2004.04.19
A42: 배명순 | B42: 000000498 | C42: 1493631 | D42: 고용노동부.감사관.감사담당관 | E42: =VLOOKUP(D42,Sheet2!$A$1:$B$733,2,0) -> 1493631 | F42: 감사담당관 | G42: 행정사무관 | H42: 010-4105-0601 | I42: 1995.11.15
A43: 오현석 | B43: 020028041 | C43: 1493631 | D43: 고용노동부.감사관.감사담당관 | E43: =VLOOKUP(D43,Sheet2!$A$1:$B$733,2,0) -> 1493631 | F43: 감사담당관 | G43: 행정사무관 | H43: 010-5030-5301 | I43: 2006.03.13
A44: 송형기 | B44: 010042255 | C44: 1493631 | D44: 고용노동부.감사관.감사담당관 | E44: =VLOOKUP(D44,Sheet2!$A$1:$B$733,2,0) -> 1493631 | F44: 감사담당관 | G44: 행정사무관 | H44: 010-2062-7912 | I44: 2007.01.02
A45: 양민호 | B45: 000001068 | C45: 1493631 | D45: 고용노동부.감사관.감사담당관 | E45: =VLOOKUP(D45,Sheet2!$A$1:$B$733,2,0) -> 1493631 | F45: 감사담당관 | G45: 행정사무관 | H45: 010-6476-2055 | I45: 2000.02.28
A46: 최진우 | B46: 030020855 | C46: 1493631 | D46: 고용노동부.감사관.감사담당관 | E46: =VLOOKUP(D46,Sheet2!$A$1:$B$733,2,0) -> 1493631 | F46: 감사담당관 | G46: 행정주사 | H46: 010-9847-3579 | I46: 2005.02.01
A47: 한상현 | B47: 010038557 | C47: 1493631 | D47: 고용노동부.감사관.감사담당관 | E47: =VLOOKUP(D47,Sheet2!$A$1:$B$733,2,0) -> 1493631 | F47: 감사담당관 | G47: 행정주사 | H47: 01074308857 | I47: 2006.09.01
A48: 강지훈 | B48: 030031180 | C48: 1493631 | D48: 고용노동부.감사관.감사담당관 | E48: =VLOOKUP(D48,Sheet2!$A$1:$B$733,2,0) -> 1493631 | F48: 감사담당관 | G48: 행정주사 | H48: 010-3138-7811 | I48: 2006.03.13
... A58: 이수연 | B58: 050009199 | C58: 1493631 | D58: 고용노동부.감사관.감사담당관 | E58: =VLOOKUP(D58,Sheet2!$A$1:$B$733,2,0) -> 1493631 | F58: 감사담당관 | G58: 행정주사보 | H58: 01027613813 | I58: 2019.08.12
A59: 이경현 | B59: 050090013 | C59: 1493631 | D59: 고용노동부.감사관.감사담당관 | E59: =VLOOKUP(D59,Sheet2!$A$1:$B$733,2,0) -> 1493631 | F59: 감사담당관 | G59: 기타
A60: 최난주 | B60: 000000402 | C60: 1493002 | D60: 고용노동부.감사관.민원운영팀 | E60: =VLOOKUP(D60,Sheet2!$A$1:$B$733,2,0) -> 1493002 | F60: 민원운영팀 | G60: 서기관 | H60: 010-5512-7162 | I60: 1991.08.01
...

Sheet Sheet2
A1: 실부서명 | B1: 기관코드
A2: 고용노동부.장관실 | B2: 1492001
A3: 고용노동부.장관실.비서실 | B3: 1492001
A4: 고용노동부.장관실.장관정책보좌관실 | B4: 1493690
A5: 고용노동부.차관실 | B5: 1492002
A6: 고용노동부.차관실.비서실 | B6: 1492002
A7: 고용노동부.대변인 | B7: 1493687
A8: 고용노동부.대변인.홍보담당관 | B8: 1492992
A9: 고용노동부.대변인.디지털소통팀 | B9: 1494930
A10: 고용노동부.감사관.감사담당관 | B10: 1493631
A11: 고용노동부.감사관.민원운영팀 | B11: 1493002
A12: 고용노동부.기획조정실 | B12: 1493633
... A70: 고용노동부.노동정책실.근로기준정책관.근로기준정책과 | B70: 1494749
A71: 고용노동부.노동정책실.근로기준정책관.근로기준정책과.공공기관 통상임금 TF | B71: 1494749
A72: 고용노동부.노동정책실.근로기준정책관.퇴직연금복지과 | B72: 1494750
A73: 고용노동부.노동정책실.근로기준정책관.고용차별개선과 | B73: 1494751
A74: 고용노동부.노동정책실.근로감독정책단.근로감독기획과 | B74: 1494967
A75: 고용노동부.노동정책실.근로감독정책단.근로감독협력과 | B75: 1494971
A76: 고용노동부.노동정책실.근로감독정책단.근로감독협력과.근로감독역량강화TF | B76: 1494971
A77: 고용노동부.운영지원과 | B77: 1493632
A78: 고용노동부.운영지원과.서무계 | B78: 1493632
A79: 고용노동부.운영지원과.인사계 | B79: 1493632
A80: 고용노동부.운영지원과.교육계 | B80: 1493632
A81: 고용노동부.운영지원과.재무계 | B81: 1493632
A82: 고용노동부.운영지원과.협력지원계 | B82: 1493632
A83: 고용노동부.운영지원과.시설계 | B83: 1493632
... A726: 고용노동부고객상담센터.인터넷상담과 | B726: 1494911
A727: 경제사회노동위원회.운영국.관리과 | B727: 1074800
A728: 경제사회노동위원회.운영국.기획과 | B728: 1074800
A729: 파견등.타행정기관 | B729: 1492000
A730: 파견등.국외훈련 | B730: 1492000
A731: 파견등.국내훈련 | B731: 1492000
A732: 파견등.국외파견 | B732: 1492000
A733: 파견등.고용부기타 | B733: 1492000

Sheet 전체현황(260202)
A1: 연번 | B1: 소속 | C1: 직급 | D1: 성명 | E1: 휴대전화 | F1: 최초임용 | G1: 개인식별아이디
A2: 1 | B2: 고용노동부 | C2: 일반직고위공무원 | D2: 양정열 | E2: 010-5312-2176 | F2: 1996.04.15 | G2: 799ed728defa108dd97c9854
A3: 2 | B3: 고용노동부 | C3: 일반직고위공무원 | D3: 정병팔 | E3: 010-6220-6896 | F3: 1989.10.05 | G3: 4fc47b400d448f9e3c38caf1
A4: 3 | B4: 고용노동부 | C4: 일반직고위공무원 | D4: 이우영 | E4: 010-5278-6493 | F4: 2001.04.09 | G4: 89b407bfe0ec10ed665bc069
A5: 4 | B5: 고용노동부 | C5: 일반직고위공무원 | D5: 박희준 | E5: 010-4801-0524 | F5: 2002.04.08 | G5: 1c4c34158af6bbb4def6ab01
A6: 5 | B6: 고용노동부 위원장 | C6: 일반직고위공무원(일반임기제) | D6: 마성균 | E6: 010-4641-9964 | F6: 1994.04.18 | G6: d0f6ea1ad3d87fcfa10f8756
A7: 6 | B7: 고용노동부 | C7: 일반직고위공무원 | D7: 윤영귀 | E7: 010-6389-1024 | F7: 1998.04.13 | G7: a07e88df72c269da57a1ba00
A8: 7 | B8: 고용노동부 | C8: 부이사관 | D8: 신호철 | E8: 010-5765-3601 | F8: 1999.04.12 | G8: fc4f1419a025fd61926373bc
A9: 8 | B9: 고용노동부 | C9: 부이사관 | D9: 양현수 | E9: 010-2525-8782 | F9: 2003.04.07 | G9: 9fc666cfd8cfbedb7b22b4e4
A10: 9 | B10: 고용노동부 과장 | C10: 부이사관 | D10: 김초경 | E10: 010-3812-8906 | F10: 1989.12.01 | G10: 8a66b185a12e4a6a3ac7d92b
A11: 10 | B11: 고용노동부 | C11: 부이사관 | D11: 오기환 | E11: 010-6373-9440 | F11: 2000.04.24 | G11: 2d520bb76a9f9df06fe1d328
A12: 11 | B12: 고용노동부 | C12: 부이사관 | D12: 홍정우 | E12: 010-5575-1517 | F12: 2001.04.09 | G12: 4ec99586b5d24cc93bab4191
... A7818: 7817 | B7818: 광주지방고용노동청 전주지청 산재예방감독과 | C7818: 행정주사보 | D7818: 이정연 | E7818: 010-5027-6361 | F7818: 2019.04.01 | G7818: 515e7563b4db871b6e6177b4
A7819: 7818 | B7819: 광주지방고용노동청 전주지청 산재예방감독과 | C7819: 보건주사보(일반임기제) | D7819: 장승아 | F7819: 2025.11.24 | G7819: 1844d1f21c0868801e82f41e
A7820: 7819 | B7820: 광주지방고용노동청 전주지청 산재예방감독과 | C7820: 공업주사보(일반임기제) | D7820: 최대현 | E7820: 010-5624-9258 | F7820: 2025.11.24 | G7820: 125708c96fb02a8b043fed55
A7821: 7820 | B7821: 광주지방고용노동청 전주지청 산재예방감독과 | C7821: 행정서기보 | D7821: 홍다빈 | E7821: 010-7673-2720 | F7821: 2024.02.05 | G7821: 8e3eef52070419bd6a18ab3d
A7822: 7821 | B7822: 광주지방고용노동청 전주지청 건설산재예방감독과 | C7822: 행정사무관 | D7822: 임학근 | E7822: 010-4609-3187 | F7822: 1995.06.12 | G7822: b9d7d1f8fc6bfbb6c706062a
A7823: 7822 | B7823: 광주지방고용노동청 전주지청 건설산재예방감독과 | C7823: 행정주사 | D7823: 한승미 | E7823: 010-9437-0123 | F7823: 1989.03.07 | G7823: 7b4607a8484d80147c0306bc
A7824: 7823 | B7824: 광주지방고용노동청 전주지청 건설산재예방감독과 | C7824: 공업주사 | D7824: 진덕용 | E7824: 010-2309-9336 | F7824: 2012.01.01 | G7824: ca129736d64ea261e9a881a1
A7825: 7824 | B7825: 광주지방고용노동청 전주지청 건설산재예방감독과 | C7825: 행정주사보 | D7825: 송하경 | E7825: 010-7277-3787 | F7825: 2015.12.28 | G7825: f364e3e1abd60c1604d51321
A7826: 7825 | B7826: 광주지방고용노동청 전주지청 건설산재예방감독과 | C7826: 시설주사보 | D7826: 김효정 | E7826: 010-3296-0554 | F7826: 2019.01.21 | G7826: 589713d2fc3a2471fd5b996c
A7827: 7826 | B7827: 광주지방고용노동청 전주지청 건설산재예방감독과 | C7827: 시설주사보 | D7827: 임채현 | E7827: 010-9027-1098 | F7827: 2021.09.27 | G7827: 2384c7dda3fba6c3b566c622
A7828: 7827 | B7828: 광주지방고용노동청 전주지청 건설산재예방감독과 | C7828: 공업주사보 | D7828: 이창주 | E7828: 010-5169-1108 | F7828: 2021.09.06 | G7828: cd2e999c1780d566833a1be4
A7829: 7828 | B7829: 광주지방고용노동청 전주지청 건설산재예방감독과 | C7829: 보건주사보(일반임기제) | D7829: 차수연 | E7829: 010-5632-2610 | F7829: 2025.12.22 | G7829: fb69e67015a9879f60e70442
A7830: 7829 | B7830: 광주지방고용노동청 전주지청 건설산재예방감독과 | C7830: 시설주사보(일반임기제) | D7830: 최길연 | E7830: 010-5234-3168 | F7830: 2025.11.24 | G7830: 203e09230de4d3e82d8842af
A7831: 7830 | B7831: 광주지방고용노동청 전주지청 건설산재예방감독과 | C7831: 시설주사보(일반임기제) | D7831: 이민재 | E7831: 010-4445-9697 | F7831: 2025.11.24 | G7831: d2022d813367c121aef0042e
... A9184: 9183 | B9184: 경기지방노동위원회 사무국 | C9184: 서기관 | D9184: 김우동 | E9184: 010-6385-2652 | F9184: 1993.04.19 | G9184: 4ce49229fa1307a640a039a1
A9185: 9184 | B9185: 경기지방노동위원회 사무국 | C9185: 행정주사 | D9185: 최병희 | F9185: 1992.09.01 | G9185: 74b406957dd9273a3ae097e1
A9186: 9185 | B9186: 경기지방노동위원회 사무국 조정과장 | C9186: 행정사무관 | D9186: 유봉현 | E9186: 010-6397-0128 | F9186: 1988.11.01 | G9186: 8e84e2cc8bd936873a26c758
A9187: 9186 | B9187: 경기지방노동위원회 사무국 조정과 | C9187: 행정주사 | D9187: 손성진 | E9187: 010-6338-2918 | F9187: 2005.07.01 | G9187: 11e6551ae781823597a91347
A9188: 9187 | B9188: 경기지방노동위원회 사무국 조정과 | C9188: 행정주사 | D9188: 이도영 | E9188: 010-8772-7292 | F9188: 2009.03.16 | G9188: 3a2985816b9c18cb5dec4f24
A9189: 9188 | B9189: 경기지방노동위원회 사무국 조정과 | C9189: 행정주사 | D9189: 박현자 | E9189: 010-3746-7366 | F9189: 1996.07.16 | G9189: ecca92c514764ca5652056ab
A9190: 9189 | B9190: 경기지방노동위원회 사무국 조정과 | C9190: 행정주사 | D9190: 박유리 | E9190: 010-2860-8534 | F9190: 2009.03.16 | G9190: 8ab4402f3df5b992f312e516
A9191: 9190 | B9191: 경기지방노동위원회 사무국 조정과 | C9191: 행정주사보 | D9191: 김은기 | E9191: 010-4303-8131 | F9191: 2010.09.10 | G9191: 13a5f92ff69058b609fba2ee
A9192: 9191 | B9192: 경기지방노동위원회 사무국 조정과 | C9192: 행정주사보 | D9192: 김란경 | E9192: 010-8823-4484 | F9192: 2020.02.10 | G9192: b794da1e2eed3dd8fa4ec0bb
A9193: 9192 | B9193: 경기지방노동위원회 사무국 조정과 | C9193: 행정주사보 | D9193: 강유나 | E9193: 01075141700 | F9193: 2016.09.12 | G9193: 0a3d21fb4230a04f577885a4
A9194: 9193 | B9194: 경기지방노동위원회 사무국 조정과 | C9194: 행정주사보 | D9194: 김형태 | E9194: 010-6378-2000 | F9194: 2017.09.27 | G9194: 811ff39e12c84e9e9a3f31aa
A9195: 9194 | B9195: 경기지방노동위원회 사무국 조정과 | C9195: 행정서기 | D9195: 임아영 | E9195: 010-5913-8958 | F9195: 2020.09.30 | G9195: 9e8156caca21daf45cbc5c59
A9196: 9195 | B9196: 경기지방노동위원회 사무국 조정과 | C9196: 행정서기 | D9196: 이재홍 | E9196: 010-5327-9841 | F9196: 2021.10.05 | G9196: f5e227032b6a51081cd5126b
A9197: 9196 | B9197: 경기지방노동위원회 사무국 조정과 | C9197: 운전서기 | D9197: 박상현 | E9197: 010-9278-4850 | F9197: 2020.02.01 | G9197: 908e4a3f00912f146c59ebbf
...
